root - ERROR - Error - 000069 - Message: timeout
  (Session info: headless chrome=78.0.3904.97)
 - Stock.run
Traceback (most recent call last):
  File "C:\Users\andrew.li\Desktop\Projects\Lim\Project_2-Forum\daily_routine_win.py", line 134, in run
    driver.get(first_page)
  File "C:\Users\andrew.li\AppData\Local\Programs\Python\Python36\lib\site-packages\selenium\webdriver\remote\webdriver.py", line 333, in get
    self.execute(Command.GET, {'url': url})
  File "C:\Users\andrew.li\AppData\Local\Programs\Python\Python36\lib\site-packages\selenium\webdriver\remote\webdriver.py", line 321, in execute
    self.error_handler.check_response(response)
  File "C:\Users\andrew.li\AppData\Local\Programs\Python\Python36\lib\site-packages\selenium\webdriver\remote\errorhandler.py", line 242, in check_response
    raise exception_class(message, screen, stacktrace)
selenium.common.exceptions.TimeoutException: Message: timeout
  (Session info: headless chrome=78.0.3904.97)

root - ERROR - Error - 000100 - Message: timeout
  (Session info: headless chrome=78.0.3904.97)
 - Stock.run
Traceback (most recent call last):
  File "C:\Users\andrew.li\Desktop\Projects\Lim\Project_2-Forum\daily_routine_win.py", line 134, in run
    driver.set_page_load_timeout(10)
  File "C:\Users\andrew.li\AppData\Local\Programs\Python\Python36\lib\site-packages\selenium\webdriver\remote\webdriver.py", line 333, in get
    self.execute(Command.GET, {'url': url})
  File "C:\Users\andrew.li\AppData\Local\Programs\Python\Python36\lib\site-packages\selenium\webdriver\remote\webdriver.py", line 321, in execute
    self.error_handler.check_response(response)
  File "C:\Users\andrew.li\AppData\Local\Programs\Python\Python36\lib\site-packages\selenium\webdriver\remote\errorhandler.py", line 242, in check_response
    raise exception_class(message, screen, stacktrace)
selenium.common.exceptions.TimeoutException: Message: timeout
  (Session info: headless chrome=78.0.3904.97)

root - ERROR - Error - 000100 - Message: timeout
  (Session info: headless chrome=78.0.3904.97)
 - Stock.run
Traceback (most recent call last):
  File "C:\Users\andrew.li\Desktop\Projects\Lim\Project_2-Forum\daily_routine_win.py", line 134, in run
    driver.set_page_load_timeout(10)
  File "C:\Users\andrew.li\AppData\Local\Programs\Python\Python36\lib\site-packages\selenium\webdriver\remote\webdriver.py", line 333, in get
    self.execute(Command.GET, {'url': url})
  File "C:\Users\andrew.li\AppData\Local\Programs\Python\Python36\lib\site-packages\selenium\webdriver\remote\webdriver.py", line 321, in execute
    self.error_handler.check_response(response)
  File "C:\Users\andrew.li\AppData\Local\Programs\Python\Python36\lib\site-packages\selenium\webdriver\remote\errorhandler.py", line 242, in check_response
    raise exception_class(message, screen, stacktrace)
selenium.common.exceptions.TimeoutException: Message: timeout
  (Session info: headless chrome=78.0.3904.97)

root - ERROR - Error - 000408 - Message: timeout
  (Session info: headless chrome=78.0.3904.97)
 - Stock.run
Traceback (most recent call last):
  File "C:\Users\andrew.li\Desktop\Projects\Lim\Project_2-Forum\daily_routine_win.py", line 134, in run
    driver.set_page_load_timeout(10)
  File "C:\Users\andrew.li\AppData\Local\Programs\Python\Python36\lib\site-packages\selenium\webdriver\remote\webdriver.py", line 333, in get
    self.execute(Command.GET, {'url': url})
  File "C:\Users\andrew.li\AppData\Local\Programs\Python\Python36\lib\site-packages\selenium\webdriver\remote\webdriver.py", line 321, in execute
    self.error_handler.check_response(response)
  File "C:\Users\andrew.li\AppData\Local\Programs\Python\Python36\lib\site-packages\selenium\webdriver\remote\errorhandler.py", line 242, in check_response
    raise exception_class(message, screen, stacktrace)
selenium.common.exceptions.TimeoutException: Message: timeout
  (Session info: headless chrome=78.0.3904.97)

root - ERROR - Error - 000415 - Message: timeout
  (Session info: headless chrome=78.0.3904.97)
 - Stock.run
Traceback (most recent call last):
  File "C:\Users\andrew.li\Desktop\Projects\Lim\Project_2-Forum\daily_routine_win.py", line 134, in run
    driver.set_page_load_timeout(10)
  File "C:\Users\andrew.li\AppData\Local\Programs\Python\Python36\lib\site-packages\selenium\webdriver\remote\webdriver.py", line 333, in get
    self.execute(Command.GET, {'url': url})
  File "C:\Users\andrew.li\AppData\Local\Programs\Python\Python36\lib\site-packages\selenium\webdriver\remote\webdriver.py", line 321, in execute
    self.error_handler.check_response(response)
  File "C:\Users\andrew.li\AppData\Local\Programs\Python\Python36\lib\site-packages\selenium\webdriver\remote\errorhandler.py", line 242, in check_response
    raise exception_class(message, screen, stacktrace)
selenium.common.exceptions.TimeoutException: Message: timeout
  (Session info: headless chrome=78.0.3904.97)

root - ERROR - Error - 000538 - Message: timeout
  (Session info: headless chrome=78.0.3904.97)
 - Stock.run
Traceback (most recent call last):
  File "C:\Users\andrew.li\Desktop\Projects\Lim\Project_2-Forum\daily_routine_win.py", line 134, in run
    driver.set_page_load_timeout(10)
  File "C:\Users\andrew.li\AppData\Local\Programs\Python\Python36\lib\site-packages\selenium\webdriver\remote\webdriver.py", line 333, in get
    self.execute(Command.GET, {'url': url})
  File "C:\Users\andrew.li\AppData\Local\Programs\Python\Python36\lib\site-packages\selenium\webdriver\remote\webdriver.py", line 321, in execute
    self.error_handler.check_response(response)
  File "C:\Users\andrew.li\AppData\Local\Programs\Python\Python36\lib\site-packages\selenium\webdriver\remote\errorhandler.py", line 242, in check_response
    raise exception_class(message, screen, stacktrace)
selenium.common.exceptions.TimeoutException: Message: timeout
  (Session info: headless chrome=78.0.3904.97)

root - ERROR - Error - 000568 - time data 2000-</html> doesn't match format specified - run_by_date
Traceback (most recent call last):
  File "C:\Users\andrew.li\AppData\Local\Programs\Python\Python36\lib\site-packages\pandas\core\arrays\datetimes.py", line 1861, in objects_to_datetime64ns
    values, tz_parsed = conversion.datetime_to_datetime64(data)
  File "pandas\_libs\tslibs\conversion.pyx", line 200, in pandas._libs.tslibs.conversion.datetime_to_datetime64
TypeError: Unrecognized value type: <class 'str'>

During handling of the above exception, another exception occurred:

Traceback (most recent call last):
  File "C:\Users\andrew.li\Desktop\Projects\Lim\Project_2-Forum\daily_routine_win.py", line 293, in run_by_date
    # print(f'Finish Downloading {ticker}')
  File "C:\Users\andrew.li\Desktop\Projects\Lim\Project_2-Forum\daily_routine_win.py", line 205, in reformat_date
    df['Time_to_cmp'] = df['Time'].apply(lambda x: '{}-'.format(2000) + x)
  File "C:\Users\andrew.li\AppData\Local\Programs\Python\Python36\lib\site-packages\pandas\core\tools\datetimes.py", line 592, in to_datetime
    values = convert_listlike(arg._values, True, format)
  File "C:\Users\andrew.li\AppData\Local\Programs\Python\Python36\lib\site-packages\pandas\core\tools\datetimes.py", line 302, in _convert_listlike_datetimes
    allow_object=True)
  File "C:\Users\andrew.li\AppData\Local\Programs\Python\Python36\lib\site-packages\pandas\core\arrays\datetimes.py", line 1866, in objects_to_datetime64ns
    raise e
  File "C:\Users\andrew.li\AppData\Local\Programs\Python\Python36\lib\site-packages\pandas\core\arrays\datetimes.py", line 1857, in objects_to_datetime64ns
    require_iso8601=require_iso8601
  File "pandas\_libs\tslib.pyx", line 460, in pandas._libs.tslib.array_to_datetime
  File "pandas\_libs\tslib.pyx", line 599, in pandas._libs.tslib.array_to_datetime
ValueError: time data 2000-</html> doesn't match format specified
root - ERROR - Error - 000568 - time data 2000-</html> doesn't match format specified - run_by_date
Traceback (most recent call last):
  File "C:\Users\andrew.li\AppData\Local\Programs\Python\Python36\lib\site-packages\pandas\core\arrays\datetimes.py", line 1861, in objects_to_datetime64ns
    values, tz_parsed = conversion.datetime_to_datetime64(data)
  File "pandas\_libs\tslibs\conversion.pyx", line 200, in pandas._libs.tslibs.conversion.datetime_to_datetime64
TypeError: Unrecognized value type: <class 'str'>

During handling of the above exception, another exception occurred:

Traceback (most recent call last):
  File "C:\Users\andrew.li\Desktop\Projects\Lim\Project_2-Forum\daily_routine_win.py", line 293, in run_by_date
    # print(f'Finish Downloading {ticker}')
  File "C:\Users\andrew.li\Desktop\Projects\Lim\Project_2-Forum\daily_routine_win.py", line 205, in reformat_date
    df['Time_to_cmp'] = df['Time'].apply(lambda x: '{}-'.format(2000) + x)
  File "C:\Users\andrew.li\AppData\Local\Programs\Python\Python36\lib\site-packages\pandas\core\tools\datetimes.py", line 592, in to_datetime
    values = convert_listlike(arg._values, True, format)
  File "C:\Users\andrew.li\AppData\Local\Programs\Python\Python36\lib\site-packages\pandas\core\tools\datetimes.py", line 302, in _convert_listlike_datetimes
    allow_object=True)
  File "C:\Users\andrew.li\AppData\Local\Programs\Python\Python36\lib\site-packages\pandas\core\arrays\datetimes.py", line 1866, in objects_to_datetime64ns
    raise e
  File "C:\Users\andrew.li\AppData\Local\Programs\Python\Python36\lib\site-packages\pandas\core\arrays\datetimes.py", line 1857, in objects_to_datetime64ns
    require_iso8601=require_iso8601
  File "pandas\_libs\tslib.pyx", line 460, in pandas._libs.tslib.array_to_datetime
  File "pandas\_libs\tslib.pyx", line 599, in pandas._libs.tslib.array_to_datetime
ValueError: time data 2000-</html> doesn't match format specified
root - ERROR - Error - 000568 - time data 2000-</html> doesn't match format specified - run_by_date
Traceback (most recent call last):
  File "C:\Users\andrew.li\AppData\Local\Programs\Python\Python36\lib\site-packages\pandas\core\arrays\datetimes.py", line 1861, in objects_to_datetime64ns
    values, tz_parsed = conversion.datetime_to_datetime64(data)
  File "pandas\_libs\tslibs\conversion.pyx", line 200, in pandas._libs.tslibs.conversion.datetime_to_datetime64
TypeError: Unrecognized value type: <class 'str'>

During handling of the above exception, another exception occurred:

Traceback (most recent call last):
  File "C:\Users\andrew.li\Desktop\Projects\Lim\Project_2-Forum\daily_routine_win.py", line 293, in run_by_date
    # print(f'Finish Downloading {ticker}')
  File "C:\Users\andrew.li\Desktop\Projects\Lim\Project_2-Forum\daily_routine_win.py", line 205, in reformat_date
    df['Time_to_cmp'] = df['Time'].apply(lambda x: '{}-'.format(2000) + x)
  File "C:\Users\andrew.li\AppData\Local\Programs\Python\Python36\lib\site-packages\pandas\core\tools\datetimes.py", line 592, in to_datetime
    values = convert_listlike(arg._values, True, format)
  File "C:\Users\andrew.li\AppData\Local\Programs\Python\Python36\lib\site-packages\pandas\core\tools\datetimes.py", line 302, in _convert_listlike_datetimes
    allow_object=True)
  File "C:\Users\andrew.li\AppData\Local\Programs\Python\Python36\lib\site-packages\pandas\core\arrays\datetimes.py", line 1866, in objects_to_datetime64ns
    raise e
  File "C:\Users\andrew.li\AppData\Local\Programs\Python\Python36\lib\site-packages\pandas\core\arrays\datetimes.py", line 1857, in objects_to_datetime64ns
    require_iso8601=require_iso8601
  File "pandas\_libs\tslib.pyx", line 460, in pandas._libs.tslib.array_to_datetime
  File "pandas\_libs\tslib.pyx", line 599, in pandas._libs.tslib.array_to_datetime
ValueError: time data 2000-</html> doesn't match format specified
root - ERROR - Error - 000568 - time data 2000-</html> doesn't match format specified - run_by_date
Traceback (most recent call last):
  File "C:\Users\andrew.li\AppData\Local\Programs\Python\Python36\lib\site-packages\pandas\core\arrays\datetimes.py", line 1861, in objects_to_datetime64ns
    values, tz_parsed = conversion.datetime_to_datetime64(data)
  File "pandas\_libs\tslibs\conversion.pyx", line 200, in pandas._libs.tslibs.conversion.datetime_to_datetime64
TypeError: Unrecognized value type: <class 'str'>

During handling of the above exception, another exception occurred:

Traceback (most recent call last):
  File "C:\Users\andrew.li\Desktop\Projects\Lim\Project_2-Forum\daily_routine_win.py", line 293, in run_by_date
    # print(f'Finish Downloading {ticker}')
  File "C:\Users\andrew.li\Desktop\Projects\Lim\Project_2-Forum\daily_routine_win.py", line 205, in reformat_date
    df['Time_to_cmp'] = df['Time'].apply(lambda x: '{}-'.format(2000) + x)
  File "C:\Users\andrew.li\AppData\Local\Programs\Python\Python36\lib\site-packages\pandas\core\tools\datetimes.py", line 592, in to_datetime
    values = convert_listlike(arg._values, True, format)
  File "C:\Users\andrew.li\AppData\Local\Programs\Python\Python36\lib\site-packages\pandas\core\tools\datetimes.py", line 302, in _convert_listlike_datetimes
    allow_object=True)
  File "C:\Users\andrew.li\AppData\Local\Programs\Python\Python36\lib\site-packages\pandas\core\arrays\datetimes.py", line 1866, in objects_to_datetime64ns
    raise e
  File "C:\Users\andrew.li\AppData\Local\Programs\Python\Python36\lib\site-packages\pandas\core\arrays\datetimes.py", line 1857, in objects_to_datetime64ns
    require_iso8601=require_iso8601
  File "pandas\_libs\tslib.pyx", line 460, in pandas._libs.tslib.array_to_datetime
  File "pandas\_libs\tslib.pyx", line 599, in pandas._libs.tslib.array_to_datetime
ValueError: time data 2000-</html> doesn't match format specified
root - ERROR - Error - 000568 - time data 2000-</html> doesn't match format specified - run_by_date
Traceback (most recent call last):
  File "C:\Users\andrew.li\AppData\Local\Programs\Python\Python36\lib\site-packages\pandas\core\arrays\datetimes.py", line 1861, in objects_to_datetime64ns
    values, tz_parsed = conversion.datetime_to_datetime64(data)
  File "pandas\_libs\tslibs\conversion.pyx", line 200, in pandas._libs.tslibs.conversion.datetime_to_datetime64
TypeError: Unrecognized value type: <class 'str'>

During handling of the above exception, another exception occurred:

Traceback (most recent call last):
  File "C:\Users\andrew.li\Desktop\Projects\Lim\Project_2-Forum\daily_routine_win.py", line 293, in run_by_date
    # print(f'Finish Downloading {ticker}')
  File "C:\Users\andrew.li\Desktop\Projects\Lim\Project_2-Forum\daily_routine_win.py", line 205, in reformat_date
    df['Time_to_cmp'] = df['Time'].apply(lambda x: '{}-'.format(2000) + x)
  File "C:\Users\andrew.li\AppData\Local\Programs\Python\Python36\lib\site-packages\pandas\core\tools\datetimes.py", line 592, in to_datetime
    values = convert_listlike(arg._values, True, format)
  File "C:\Users\andrew.li\AppData\Local\Programs\Python\Python36\lib\site-packages\pandas\core\tools\datetimes.py", line 302, in _convert_listlike_datetimes
    allow_object=True)
  File "C:\Users\andrew.li\AppData\Local\Programs\Python\Python36\lib\site-packages\pandas\core\arrays\datetimes.py", line 1866, in objects_to_datetime64ns
    raise e
  File "C:\Users\andrew.li\AppData\Local\Programs\Python\Python36\lib\site-packages\pandas\core\arrays\datetimes.py", line 1857, in objects_to_datetime64ns
    require_iso8601=require_iso8601
  File "pandas\_libs\tslib.pyx", line 460, in pandas._libs.tslib.array_to_datetime
  File "pandas\_libs\tslib.pyx", line 599, in pandas._libs.tslib.array_to_datetime
ValueError: time data 2000-</html> doesn't match format specified
root - ERROR - Error - 000568 - time data 2000-</html> doesn't match format specified - run_by_date
Traceback (most recent call last):
  File "C:\Users\andrew.li\AppData\Local\Programs\Python\Python36\lib\site-packages\pandas\core\arrays\datetimes.py", line 1861, in objects_to_datetime64ns
    values, tz_parsed = conversion.datetime_to_datetime64(data)
  File "pandas\_libs\tslibs\conversion.pyx", line 200, in pandas._libs.tslibs.conversion.datetime_to_datetime64
TypeError: Unrecognized value type: <class 'str'>

During handling of the above exception, another exception occurred:

Traceback (most recent call last):
  File "C:\Users\andrew.li\Desktop\Projects\Lim\Project_2-Forum\daily_routine_win.py", line 293, in run_by_date
    # print(f'Finish Downloading {ticker}')
  File "C:\Users\andrew.li\Desktop\Projects\Lim\Project_2-Forum\daily_routine_win.py", line 205, in reformat_date
    df['Time_to_cmp'] = df['Time'].apply(lambda x: '{}-'.format(2000) + x)
  File "C:\Users\andrew.li\AppData\Local\Programs\Python\Python36\lib\site-packages\pandas\core\tools\datetimes.py", line 592, in to_datetime
    values = convert_listlike(arg._values, True, format)
  File "C:\Users\andrew.li\AppData\Local\Programs\Python\Python36\lib\site-packages\pandas\core\tools\datetimes.py", line 302, in _convert_listlike_datetimes
    allow_object=True)
  File "C:\Users\andrew.li\AppData\Local\Programs\Python\Python36\lib\site-packages\pandas\core\arrays\datetimes.py", line 1866, in objects_to_datetime64ns
    raise e
  File "C:\Users\andrew.li\AppData\Local\Programs\Python\Python36\lib\site-packages\pandas\core\arrays\datetimes.py", line 1857, in objects_to_datetime64ns
    require_iso8601=require_iso8601
  File "pandas\_libs\tslib.pyx", line 460, in pandas._libs.tslib.array_to_datetime
  File "pandas\_libs\tslib.pyx", line 599, in pandas._libs.tslib.array_to_datetime
ValueError: time data 2000-</html> doesn't match format specified
root - ERROR - Error - 000625 - Message: timeout
  (Session info: headless chrome=78.0.3904.97)
 - Stock.run
Traceback (most recent call last):
  File "C:\Users\andrew.li\Desktop\Projects\Lim\Project_2-Forum\daily_routine_win.py", line 134, in run
    driver.set_page_load_timeout(10)
  File "C:\Users\andrew.li\AppData\Local\Programs\Python\Python36\lib\site-packages\selenium\webdriver\remote\webdriver.py", line 333, in get
    self.execute(Command.GET, {'url': url})
  File "C:\Users\andrew.li\AppData\Local\Programs\Python\Python36\lib\site-packages\selenium\webdriver\remote\webdriver.py", line 321, in execute
    self.error_handler.check_response(response)
  File "C:\Users\andrew.li\AppData\Local\Programs\Python\Python36\lib\site-packages\selenium\webdriver\remote\errorhandler.py", line 242, in check_response
    raise exception_class(message, screen, stacktrace)
selenium.common.exceptions.TimeoutException: Message: timeout
  (Session info: headless chrome=78.0.3904.97)

root - ERROR - Error - 000627 - Message: timeout
  (Session info: headless chrome=78.0.3904.97)
 - Stock.run
Traceback (most recent call last):
  File "C:\Users\andrew.li\Desktop\Projects\Lim\Project_2-Forum\daily_routine_win.py", line 134, in run
    driver.set_page_load_timeout(10)
  File "C:\Users\andrew.li\AppData\Local\Programs\Python\Python36\lib\site-packages\selenium\webdriver\remote\webdriver.py", line 333, in get
    self.execute(Command.GET, {'url': url})
  File "C:\Users\andrew.li\AppData\Local\Programs\Python\Python36\lib\site-packages\selenium\webdriver\remote\webdriver.py", line 321, in execute
    self.error_handler.check_response(response)
  File "C:\Users\andrew.li\AppData\Local\Programs\Python\Python36\lib\site-packages\selenium\webdriver\remote\errorhandler.py", line 242, in check_response
    raise exception_class(message, screen, stacktrace)
selenium.common.exceptions.TimeoutException: Message: timeout
  (Session info: headless chrome=78.0.3904.97)

root - ERROR - Error - 'NoneType' object has no attribute 'text' - reformat_date - find_year_loop
Traceback (most recent call last):
  File "C:\Users\andrew.li\Desktop\Projects\Lim\Project_2-Forum\daily_routine_win.py", line 248, in reformat_date
    soup = bs4.BeautifulSoup(page, 'html.parser')
AttributeError: 'NoneType' object has no attribute 'text'
root - ERROR - Error - 000630 - 'NoneType' object is not subscriptable - run_by_date
Traceback (most recent call last):
  File "C:\Users\andrew.li\Desktop\Projects\Lim\Project_2-Forum\daily_routine_win.py", line 294, in run_by_date
    formated_df = stock.reformat_date(df)
TypeError: 'NoneType' object is not subscriptable
root - ERROR - Error - 000630 - Message: timeout
  (Session info: headless chrome=78.0.3904.97)
 - Stock.run
Traceback (most recent call last):
  File "C:\Users\andrew.li\Desktop\Projects\Lim\Project_2-Forum\daily_routine_win.py", line 134, in run
    driver.set_page_load_timeout(10)
  File "C:\Users\andrew.li\AppData\Local\Programs\Python\Python36\lib\site-packages\selenium\webdriver\remote\webdriver.py", line 333, in get
    self.execute(Command.GET, {'url': url})
  File "C:\Users\andrew.li\AppData\Local\Programs\Python\Python36\lib\site-packages\selenium\webdriver\remote\webdriver.py", line 321, in execute
    self.error_handler.check_response(response)
  File "C:\Users\andrew.li\AppData\Local\Programs\Python\Python36\lib\site-packages\selenium\webdriver\remote\errorhandler.py", line 242, in check_response
    raise exception_class(message, screen, stacktrace)
selenium.common.exceptions.TimeoutException: Message: timeout
  (Session info: headless chrome=78.0.3904.97)

root - ERROR - Error - 000630 - Message: timeout
  (Session info: headless chrome=78.0.3904.97)
 - Stock.run
Traceback (most recent call last):
  File "C:\Users\andrew.li\Desktop\Projects\Lim\Project_2-Forum\daily_routine_win.py", line 134, in run
    driver.set_page_load_timeout(10)
  File "C:\Users\andrew.li\AppData\Local\Programs\Python\Python36\lib\site-packages\selenium\webdriver\remote\webdriver.py", line 333, in get
    self.execute(Command.GET, {'url': url})
  File "C:\Users\andrew.li\AppData\Local\Programs\Python\Python36\lib\site-packages\selenium\webdriver\remote\webdriver.py", line 321, in execute
    self.error_handler.check_response(response)
  File "C:\Users\andrew.li\AppData\Local\Programs\Python\Python36\lib\site-packages\selenium\webdriver\remote\errorhandler.py", line 242, in check_response
    raise exception_class(message, screen, stacktrace)
selenium.common.exceptions.TimeoutException: Message: timeout
  (Session info: headless chrome=78.0.3904.97)

root - ERROR - Error - 000630 - Message: timeout
  (Session info: headless chrome=78.0.3904.97)
 - Stock.run
Traceback (most recent call last):
  File "C:\Users\andrew.li\Desktop\Projects\Lim\Project_2-Forum\daily_routine_win.py", line 134, in run
    driver.set_page_load_timeout(10)
  File "C:\Users\andrew.li\AppData\Local\Programs\Python\Python36\lib\site-packages\selenium\webdriver\remote\webdriver.py", line 333, in get
    self.execute(Command.GET, {'url': url})
  File "C:\Users\andrew.li\AppData\Local\Programs\Python\Python36\lib\site-packages\selenium\webdriver\remote\webdriver.py", line 321, in execute
    self.error_handler.check_response(response)
  File "C:\Users\andrew.li\AppData\Local\Programs\Python\Python36\lib\site-packages\selenium\webdriver\remote\errorhandler.py", line 242, in check_response
    raise exception_class(message, screen, stacktrace)
selenium.common.exceptions.TimeoutException: Message: timeout
  (Session info: headless chrome=78.0.3904.97)

root - ERROR - Error - 000630 - Message: timeout
  (Session info: headless chrome=78.0.3904.97)
 - Stock.run
Traceback (most recent call last):
  File "C:\Users\andrew.li\Desktop\Projects\Lim\Project_2-Forum\daily_routine_win.py", line 134, in run
    driver.set_page_load_timeout(10)
  File "C:\Users\andrew.li\AppData\Local\Programs\Python\Python36\lib\site-packages\selenium\webdriver\remote\webdriver.py", line 333, in get
    self.execute(Command.GET, {'url': url})
  File "C:\Users\andrew.li\AppData\Local\Programs\Python\Python36\lib\site-packages\selenium\webdriver\remote\webdriver.py", line 321, in execute
    self.error_handler.check_response(response)
  File "C:\Users\andrew.li\AppData\Local\Programs\Python\Python36\lib\site-packages\selenium\webdriver\remote\errorhandler.py", line 242, in check_response
    raise exception_class(message, screen, stacktrace)
selenium.common.exceptions.TimeoutException: Message: timeout
  (Session info: headless chrome=78.0.3904.97)

root - ERROR - Error - 000630 - Message: timeout
  (Session info: headless chrome=78.0.3904.97)
 - Stock.run
Traceback (most recent call last):
  File "C:\Users\andrew.li\Desktop\Projects\Lim\Project_2-Forum\daily_routine_win.py", line 134, in run
    driver.set_page_load_timeout(10)
  File "C:\Users\andrew.li\AppData\Local\Programs\Python\Python36\lib\site-packages\selenium\webdriver\remote\webdriver.py", line 333, in get
    self.execute(Command.GET, {'url': url})
  File "C:\Users\andrew.li\AppData\Local\Programs\Python\Python36\lib\site-packages\selenium\webdriver\remote\webdriver.py", line 321, in execute
    self.error_handler.check_response(response)
  File "C:\Users\andrew.li\AppData\Local\Programs\Python\Python36\lib\site-packages\selenium\webdriver\remote\errorhandler.py", line 242, in check_response
    raise exception_class(message, screen, stacktrace)
selenium.common.exceptions.TimeoutException: Message: timeout
  (Session info: headless chrome=78.0.3904.97)

