root - ERROR - Error - 603288 - Message: timeout
  (Session info: headless chrome=78.0.3904.97)
 - Stock.run
Traceback (most recent call last):
  File "C:\Users\andrew.li\Desktop\Projects\Lim\Project_2-Forum\daily_routine_win.py", line 131, in call_webdriver
    driver.get(first_page)
  File "C:\Users\andrew.li\AppData\Local\Programs\Python\Python36\lib\site-packages\selenium\webdriver\remote\webdriver.py", line 333, in get
    self.execute(Command.GET, {'url': url})
  File "C:\Users\andrew.li\AppData\Local\Programs\Python\Python36\lib\site-packages\selenium\webdriver\remote\webdriver.py", line 321, in execute
    self.error_handler.check_response(response)
  File "C:\Users\andrew.li\AppData\Local\Programs\Python\Python36\lib\site-packages\selenium\webdriver\remote\errorhandler.py", line 242, in check_response
    raise exception_class(message, screen, stacktrace)
selenium.common.exceptions.TimeoutException: Message: timeout
  (Session info: headless chrome=78.0.3904.97)

root - ERROR - Error - 'http://guba.eastmoney.com/news,600703,887077893.html' - links_reformatting
Traceback (most recent call last):
  File "C:\Users\andrew.li\Desktop\Projects\Lim\Project_2-Forum\daily_routine_win.py", line 249, in reformat_date
    sorted_all_websites = [self.all_websites[link] for link in links]
  File "C:\Users\andrew.li\Desktop\Projects\Lim\Project_2-Forum\daily_routine_win.py", line 249, in <listcomp>
    sorted_all_websites = [self.all_websites[link] for link in links]
KeyError: 'http://guba.eastmoney.com/news,600703,887077893.html'
root - ERROR - Error - 600703 - 'NoneType' object is not subscriptable - run_by_date
Traceback (most recent call last):
  File "C:\Users\andrew.li\Desktop\Projects\Lim\Project_2-Forum\daily_routine_win.py", line 304, in run_by_date
    formated_df['Time'] = formated_df['Time'].apply(lambda row: dt.datetime.strptime(row, '%Y-%m-%d %H:%M'))
TypeError: 'NoneType' object is not subscriptable
root - ERROR - Error - 'http://guba.eastmoney.com/news,603156,887075569.html' - links_reformatting
Traceback (most recent call last):
  File "C:\Users\andrew.li\Desktop\Projects\Lim\Project_2-Forum\daily_routine_win.py", line 249, in reformat_date
    sorted_all_websites = [self.all_websites[link] for link in links]
  File "C:\Users\andrew.li\Desktop\Projects\Lim\Project_2-Forum\daily_routine_win.py", line 249, in <listcomp>
    sorted_all_websites = [self.all_websites[link] for link in links]
KeyError: 'http://guba.eastmoney.com/news,603156,887075569.html'
root - ERROR - Error - 603156 - 'NoneType' object is not subscriptable - run_by_date
Traceback (most recent call last):
  File "C:\Users\andrew.li\Desktop\Projects\Lim\Project_2-Forum\daily_routine_win.py", line 304, in run_by_date
    formated_df['Time'] = formated_df['Time'].apply(lambda row: dt.datetime.strptime(row, '%Y-%m-%d %H:%M'))
TypeError: 'NoneType' object is not subscriptable
: Message: timeout
  (Session info: headless chrome=78.0.3904.97)

root - ERROR - Error - 601577 - Message: timeout
  (Session info: headless chrome=78.0.3904.97)
 - Stock.run
Traceback (most recent call last):
  File "C:\Users\andrew.li\Desktop\Projects\Lim\Project_2-Forum\daily_routine_win.py", line 131, in call_webdriver
    driver.get(first_page)
  File "C:\Users\andrew.li\AppData\Local\Programs\Python\Python36\lib\site-packages\selenium\webdriver\remote\webdriver.py", line 333, in get
    self.execute(Command.GET, {'url': url})
  File "C:\Users\andrew.li\AppData\Local\Programs\Python\Python36\lib\site-packages\selenium\webdriver\remote\webdriver.py", line 321, in execute
    self.error_handler.check_response(response)
  File "C:\Users\andrew.li\AppData\Local\Programs\Python\Python36\lib\site-packages\selenium\webdriver\remote\errorhandler.py", line 242, in check_response
    raise exception_class(message, screen, stacktrace)
selenium.common.exceptions.TimeoutException: Message: timeout
  (Session info: headless chrome=78.0.3904.97)

root - ERROR - Timeout - http://guba.eastmoney.com/list,601628,f_2.html
Traceback (most recent call last):
  File "C:\Users\andrew.li\AppData\Local\Programs\Python\Python36\lib\site-packages\urllib3\connectionpool.py", line 387, in _make_request
    six.raise_from(e, None)
  File "<string>", line 2, in raise_from
  File "C:\Users\andrew.li\AppData\Local\Programs\Python\Python36\lib\site-packages\urllib3\connectionpool.py", line 383, in _make_request
    httplib_response = conn.getresponse()
  File "C:\Users\andrew.li\AppData\Local\Programs\Python\Python36\lib\http\client.py", line 1331, in getresponse
    response.begin()
  File "C:\Users\andrew.li\AppData\Local\Programs\Python\Python36\lib\http\client.py", line 297, in begin
    version, status, reason = self._read_status()
  File "C:\Users\andrew.li\AppData\Local\Programs\Python\Python36\lib\http\client.py", line 258, in _read_status
    line = str(self.fp.readline(_MAXLINE + 1), "iso-8859-1")
  File "C:\Users\andrew.li\AppData\Local\Programs\Python\Python36\lib\socket.py", line 586, in readinto
    return self._sock.recv_into(b)
socket.timeout: timed out

During handling of the above exception, another exception occurred:

Traceback (most recent call last):
  File "C:\Users\andrew.li\AppData\Local\Programs\Python\Python36\lib\site-packages\requests\adapters.py", line 440, in send
    timeout=timeout
  File "C:\Users\andrew.li\AppData\Local\Programs\Python\Python36\lib\site-packages\urllib3\connectionpool.py", line 639, in urlopen
    _stacktrace=sys.exc_info()[2])
  File "C:\Users\andrew.li\AppData\Local\Programs\Python\Python36\lib\site-packages\urllib3\util\retry.py", line 357, in increment
    raise six.reraise(type(error), error, _stacktrace)
  File "C:\Users\andrew.li\AppData\Local\Programs\Python\Python36\lib\site-packages\urllib3\packages\six.py", line 686, in reraise
    raise value
  File "C:\Users\andrew.li\AppData\Local\Programs\Python\Python36\lib\site-packages\urllib3\connectionpool.py", line 601, in urlopen
    chunked=chunked)
  File "C:\Users\andrew.li\AppData\Local\Programs\Python\Python36\lib\site-packages\urllib3\connectionpool.py", line 389, in _make_request
    self._raise_timeout(err=e, url=url, timeout_value=read_timeout)
  File "C:\Users\andrew.li\AppData\Local\Programs\Python\Python36\lib\site-packages\urllib3\connectionpool.py", line 309, in _raise_timeout
    raise ReadTimeoutError(self, url, "Read timed out. (read timeout=%s)" % timeout_value)
urllib3.exceptions.ReadTimeoutError: HTTPConnectionPool(host='guba.eastmoney.com', port=80): Read timed out. (read timeout=30)

During handling of the above exception, another exception occurred:

Traceback (most recent call last):
  File "C:\Users\andrew.li\Desktop\Projects\Lim\Project_2-Forum\daily_routine_win.py", line 185, in download_site
    with session.request(method='GET', url=url, timeout=30) as response:
  File "C:\Users\andrew.li\AppData\Local\Programs\Python\Python36\lib\site-packages\requests\sessions.py", line 508, in request
    resp = self.send(prep, **send_kwargs)
  File "C:\Users\andrew.li\AppData\Local\Programs\Python\Python36\lib\site-packages\requests\sessions.py", line 618, in send
    r = adapter.send(request, **kwargs)
  File "C:\Users\andrew.li\AppData\Local\Programs\Python\Python36\lib\site-packages\requests\adapters.py", line 521, in send
    raise ReadTimeout(e, request=request)
requests.exceptions.ReadTimeout: HTTPConnectionPool(host='guba.eastmoney.com', port=80): Read timed out. (read timeout=30)
root - ERROR - Timeout - http://guba.eastmoney.com/list,601628,f_4.html
Traceback (most recent call last):
  File "C:\Users\andrew.li\AppData\Local\Programs\Python\Python36\lib\site-packages\urllib3\connectionpool.py", line 387, in _make_request
    six.raise_from(e, None)
  File "<string>", line 2, in raise_from
  File "C:\Users\andrew.li\AppData\Local\Programs\Python\Python36\lib\site-packages\urllib3\connectionpool.py", line 383, in _make_request
    httplib_response = conn.getresponse()
  File "C:\Users\andrew.li\AppData\Local\Programs\Python\Python36\lib\http\client.py", line 1331, in getresponse
    response.begin()
  File "C:\Users\andrew.li\AppData\Local\Programs\Python\Python36\lib\http\client.py", line 297, in begin
    version, status, reason = self._read_status()
  File "C:\Users\andrew.li\AppData\Local\Programs\Python\Python36\lib\http\client.py", line 258, in _read_status
    line = str(self.fp.readline(_MAXLINE + 1), "iso-8859-1")
  File "C:\Users\andrew.li\AppData\Local\Programs\Python\Python36\lib\socket.py", line 586, in readinto
    return self._sock.recv_into(b)
socket.timeout: timed out

During handling of the above exception, another exception occurred:

Traceback (most recent call last):
  File "C:\Users\andrew.li\AppData\Local\Programs\Python\Python36\lib\site-packages\requests\adapters.py", line 440, in send
    timeout=timeout
  File "C:\Users\andrew.li\AppData\Local\Programs\Python\Python36\lib\site-packages\urllib3\connectionpool.py", line 639, in urlopen
    _stacktrace=sys.exc_info()[2])
  File "C:\Users\andrew.li\AppData\Local\Programs\Python\Python36\lib\site-packages\urllib3\util\retry.py", line 357, in increment
    raise six.reraise(type(error), error, _stacktrace)
  File "C:\Users\andrew.li\AppData\Local\Programs\Python\Python36\lib\site-packages\urllib3\packages\six.py", line 686, in reraise
    raise value
  File "C:\Users\andrew.li\AppData\Local\Programs\Python\Python36\lib\site-packages\urllib3\connectionpool.py", line 601, in urlopen
    chunked=chunked)
  File "C:\Users\andrew.li\AppData\Local\Programs\Python\Python36\lib\site-packages\urllib3\connectionpool.py", line 389, in _make_request
    self._raise_timeout(err=e, url=url, timeout_value=read_timeout)
  File "C:\Users\andrew.li\AppData\Local\Programs\Python\Python36\lib\site-packages\urllib3\connectionpool.py", line 309, in _raise_timeout
    raise ReadTimeoutError(self, url, "Read timed out. (read timeout=%s)" % timeout_value)
urllib3.exceptions.ReadTimeoutError: HTTPConnectionPool(host='guba.eastmoney.com', port=80): Read timed out. (read timeout=30)

During handling of the above exception, another exception occurred:

Traceback (most recent call last):
  File "C:\Users\andrew.li\Desktop\Projects\Lim\Project_2-Forum\daily_routine_win.py", line 185, in download_site
    with session.request(method='GET', url=url, timeout=30) as response:
  File "C:\Users\andrew.li\AppData\Local\Programs\Python\Python36\lib\site-packages\requests\sessions.py", line 508, in request
    resp = self.send(prep, **send_kwargs)
  File "C:\Users\andrew.li\AppData\Local\Programs\Python\Python36\lib\site-packages\requests\sessions.py", line 618, in send
    r = adapter.send(request, **kwargs)
  File "C:\Users\andrew.li\AppData\Local\Programs\Python\Python36\lib\site-packages\requests\adapters.py", line 521, in send
    raise ReadTimeout(e, request=request)
requests.exceptions.ReadTimeout: HTTPConnectionPool(host='guba.eastmoney.com', port=80): Read timed out. (read timeout=30)
root - ERROR - Timeout - http://guba.eastmoney.com/list,601628,f_8.html
Traceback (most recent call last):
  File "C:\Users\andrew.li\AppData\Local\Programs\Python\Python36\lib\site-packages\urllib3\connectionpool.py", line 387, in _make_request
    six.raise_from(e, None)
  File "<string>", line 2, in raise_from
  File "C:\Users\andrew.li\AppData\Local\Programs\Python\Python36\lib\site-packages\urllib3\connectionpool.py", line 383, in _make_request
    httplib_response = conn.getresponse()
  File "C:\Users\andrew.li\AppData\Local\Programs\Python\Python36\lib\http\client.py", line 1331, in getresponse
    response.begin()
  File "C:\Users\andrew.li\AppData\Local\Programs\Python\Python36\lib\http\client.py", line 297, in begin
    version, status, reason = self._read_status()
  File "C:\Users\andrew.li\AppData\Local\Programs\Python\Python36\lib\http\client.py", line 258, in _read_status
    line = str(self.fp.readline(_MAXLINE + 1), "iso-8859-1")
  File "C:\Users\andrew.li\AppData\Local\Programs\Python\Python36\lib\socket.py", line 586, in readinto
    return self._sock.recv_into(b)
socket.timeout: timed out

During handling of the above exception, another exception occurred:

Traceback (most recent call last):
  File "C:\Users\andrew.li\AppData\Local\Programs\Python\Python36\lib\site-packages\requests\adapters.py", line 440, in send
    timeout=timeout
  File "C:\Users\andrew.li\AppData\Local\Programs\Python\Python36\lib\site-packages\urllib3\connectionpool.py", line 639, in urlopen
    _stacktrace=sys.exc_info()[2])
  File "C:\Users\andrew.li\AppData\Local\Programs\Python\Python36\lib\site-packages\urllib3\util\retry.py", line 357, in increment
    raise six.reraise(type(error), error, _stacktrace)
  File "C:\Users\andrew.li\AppData\Local\Programs\Python\Python36\lib\site-packages\urllib3\packages\six.py", line 686, in reraise
    raise value
  File "C:\Users\andrew.li\AppData\Local\Programs\Python\Python36\lib\site-packages\urllib3\connectionpool.py", line 601, in urlopen
    chunked=chunked)
  File "C:\Users\andrew.li\AppData\Local\Programs\Python\Python36\lib\site-packages\urllib3\connectionpool.py", line 389, in _make_request
    self._raise_timeout(err=e, url=url, timeout_value=read_timeout)
  File "C:\Users\andrew.li\AppData\Local\Programs\Python\Python36\lib\site-packages\urllib3\connectionpool.py", line 309, in _raise_timeout
    raise ReadTimeoutError(self, url, "Read timed out. (read timeout=%s)" % timeout_value)
urllib3.exceptions.ReadTimeoutError: HTTPConnectionPool(host='guba.eastmoney.com', port=80): Read timed out. (read timeout=30)

During handling of the above exception, another exception occurred:

Traceback (most recent call last):
  File "C:\Users\andrew.li\Desktop\Projects\Lim\Project_2-Forum\daily_routine_win.py", line 185, in download_site
    with session.request(method='GET', url=url, timeout=30) as response:
  File "C:\Users\andrew.li\AppData\Local\Programs\Python\Python36\lib\site-packages\requests\sessions.py", line 508, in request
    resp = self.send(prep, **send_kwargs)
  File "C:\Users\andrew.li\AppData\Local\Programs\Python\Python36\lib\site-packages\requests\sessions.py", line 618, in send
    r = adapter.send(request, **kwargs)
  File "C:\Users\andrew.li\AppData\Local\Programs\Python\Python36\lib\site-packages\requests\adapters.py", line 521, in send
    raise ReadTimeout(e, request=request)
requests.exceptions.ReadTimeout: HTTPConnectionPool(host='guba.eastmoney.com', port=80): Read timed out. (read timeout=30)
root - ERROR - Timeout - http://guba.eastmoney.com/list,601628,f_9.html
Traceback (most recent call last):
  File "C:\Users\andrew.li\AppData\Local\Programs\Python\Python36\lib\site-packages\urllib3\connectionpool.py", line 387, in _make_request
    six.raise_from(e, None)
  File "<string>", line 2, in raise_from
  File "C:\Users\andrew.li\AppData\Local\Programs\Python\Python36\lib\site-packages\urllib3\connectionpool.py", line 383, in _make_request
    httplib_response = conn.getresponse()
  File "C:\Users\andrew.li\AppData\Local\Programs\Python\Python36\lib\http\client.py", line 1331, in getresponse
    response.begin()
  File "C:\Users\andrew.li\AppData\Local\Programs\Python\Python36\lib\http\client.py", line 297, in begin
    version, status, reason = self._read_status()
  File "C:\Users\andrew.li\AppData\Local\Programs\Python\Python36\lib\http\client.py", line 258, in _read_status
    line = str(self.fp.readline(_MAXLINE + 1), "iso-8859-1")
  File "C:\Users\andrew.li\AppData\Local\Programs\Python\Python36\lib\socket.py", line 586, in readinto
    return self._sock.recv_into(b)
socket.timeout: timed out

During handling of the above exception, another exception occurred:

Traceback (most recent call last):
  File "C:\Users\andrew.li\AppData\Local\Programs\Python\Python36\lib\site-packages\requests\adapters.py", line 440, in send
    timeout=timeout
  File "C:\Users\andrew.li\AppData\Local\Programs\Python\Python36\lib\site-packages\urllib3\connectionpool.py", line 639, in urlopen
    _stacktrace=sys.exc_info()[2])
  File "C:\Users\andrew.li\AppData\Local\Programs\Python\Python36\lib\site-packages\urllib3\util\retry.py", line 357, in increment
    raise six.reraise(type(error), error, _stacktrace)
  File "C:\Users\andrew.li\AppData\Local\Programs\Python\Python36\lib\site-packages\urllib3\packages\six.py", line 686, in reraise
    raise value
  File "C:\Users\andrew.li\AppData\Local\Programs\Python\Python36\lib\site-packages\urllib3\connectionpool.py", line 601, in urlopen
    chunked=chunked)
  File "C:\Users\andrew.li\AppData\Local\Programs\Python\Python36\lib\site-packages\urllib3\connectionpool.py", line 389, in _make_request
    self._raise_timeout(err=e, url=url, timeout_value=read_timeout)
  File "C:\Users\andrew.li\AppData\Local\Programs\Python\Python36\lib\site-packages\urllib3\connectionpool.py", line 309, in _raise_timeout
    raise ReadTimeoutError(self, url, "Read timed out. (read timeout=%s)" % timeout_value)
urllib3.exceptions.ReadTimeoutError: HTTPConnectionPool(host='guba.eastmoney.com', port=80): Read timed out. (read timeout=30)

During handling of the above exception, another exception occurred:

Traceback (most recent call last):
  File "C:\Users\andrew.li\Desktop\Projects\Lim\Project_2-Forum\daily_routine_win.py", line 185, in download_site
    with session.request(method='GET', url=url, timeout=30) as response:
  File "C:\Users\andrew.li\AppData\Local\Programs\Python\Python36\lib\site-packages\requests\sessions.py", line 508, in request
    resp = self.send(prep, **send_kwargs)
  File "C:\Users\andrew.li\AppData\Local\Programs\Python\Python36\lib\site-packages\requests\sessions.py", line 618, in send
    r = adapter.send(request, **kwargs)
  File "C:\Users\andrew.li\AppData\Local\Programs\Python\Python36\lib\site-packages\requests\adapters.py", line 521, in send
    raise ReadTimeout(e, request=request)
requests.exceptions.ReadTimeout: HTTPConnectionPool(host='guba.eastmoney.com', port=80): Read timed out. (read timeout=30)
